Traceback (most recent call last):
  File "/usr/lib/python2.7/logging/__init__.py", line 850, in emit
    msg = self.format(record)
  File "/usr/lib/python2.7/logging/__init__.py", line 723, in format
    return fmt.format(record)
  File "/usr/lib/python2.7/logging/__init__.py", line 464, in format
    record.message = record.getMessage()
  File "/usr/lib/python2.7/logging/__init__.py", line 328, in getMessage
    msg = msg % self.args
TypeError: %d format: a number is required, not str
Logged from file TaskExecutor.py, line 75
Exception in thread Thread-1:
Traceback (most recent call last):
  File "/usr/lib/python2.7/threading.py", line 552, in __bootstrap_inner
    self.run()
  File "/tmp/abc/bin/TaskExecutor.py", line 51, in run
    self.__write("ALIVE")
  File "/tmp/abc/bin/TaskExecutor.py", line 82, in __write
    self.__client.write(data)
  File "/tmp/abc/bin/TaskExecutor.py", line 36, in write
    self.send("%4d%s"%(len(data), data))
  File "/usr/lib/python2.7/asyncore.py", line 374, in send
    result = self.socket.send(data)
error: [Errno 111] Connection refused

Spawn command [python /tmp/abc/bin/TaskExecutor.py --nospawn --output /tmp/abc/output --reportInterval 1 --controller 192.168.100.101:9000 --exec python /tmp/abc/TestTimeout.py 3]
Traceback (most recent call last):
  File "/usr/lib/python2.7/logging/__init__.py", line 850, in emit
    msg = self.format(record)
  File "/usr/lib/python2.7/logging/__init__.py", line 723, in format
    return fmt.format(record)
  File "/usr/lib/python2.7/logging/__init__.py", line 464, in format
    record.message = record.getMessage()
  File "/usr/lib/python2.7/logging/__init__.py", line 328, in getMessage
    msg = msg % self.args
TypeError: %d format: a number is required, not str
Logged from file TaskExecutor.py, line 75
Exception in thread Thread-1:
Traceback (most recent call last):
  File "/usr/lib/python2.7/threading.py", line 552, in __bootstrap_inner
    self.run()
  File "/tmp/abc/bin/TaskExecutor.py", line 51, in run
    self.__write("ALIVE")
  File "/tmp/abc/bin/TaskExecutor.py", line 82, in __write
    self.__client.write(data)
  File "/tmp/abc/bin/TaskExecutor.py", line 36, in write
    self.send("%4d%s"%(len(data), data))
  File "/usr/lib/python2.7/asyncore.py", line 374, in send
    result = self.socket.send(data)
error: [Errno 111] Connection refused

Spawn command [python /tmp/abc/bin/TaskExecutor.py --nospawn --output /tmp/abc/output --reportInterval 1 --controller 192.168.100.101:9000 --exec python /tmp/abc/TestTimeout.py 3]
